Workbook

Sheet Sheet1
A1: 순번 | B1: 국가 | C1: 발명의 명칭 | D1: 열1 | E1: 분류 | F1: 등록번호 | G1: 등록일자 | H1: 출원인 | I1: 국제출원번호 | J1: 국제출원일자 | K1: 국제공개번호 | L1: 국제공개일자 | M1: 요약 | N1: 대리인 | O1: 발명자 | P1: 발명자수 | Q1: 반영비율 | R1: 점수
A2: 1 | B2: US | C2: Measurement for space reuse in multi-AP system | D2: =COUNTIF(Sheet2!I:I, 표1_3[[#This Row],[등록번호]]) -> 0 | E2: B2 | F2: 12414050 | G2: 2025.09.09 | H2: LG ELECTRONICS INC. | I2: PCT/KR2020/018882 | J2: 20201222 | K2: WO2021172727 | L2: 2021.09.02 | M2: A method performed at a sharing access point (AP) of a wireless local area network (LAN) system may comprise the steps of: transmitting, to a first station (STA), a first measurement notification frame requesting measurement of a received signal strength indicator (RSSI); transmitting, to the first STA, a first measurement request frame for requesting a first path loss value which is path loss information of an overlapping basic service set (OBSS) AP and the first STA and an acceptable receiver interference level (ARIL) value; receiving, from the first STA, a first measurement report frame including the first path loss and a first ARIL value of the first STA; and transmitting, to the first STA, first data. | N2: BRYAN CAVE LEIGHTON PAISNER LLP | O2: Sungjin Park|Jeongki Kim|Jinsoo Choi|Namyeong Kim|Taewon Song|Insun Jang | P2: =COUNTA(_xlfn.TEXTSPLIT(표1_3[[#This Row],[발명자]], "|")) -> 6 | Q2: =1/표1_3[[#This Row],[발명자수]] -> 0.16666667 | R2: =300*표1_3[[#This Row],[반영비율]] -> 50
A3: 2 | B3: US | C3: Transmission of capability information about link | D3: =COUNTIF(Sheet2!I:I, 표1_3[[#This Row],[등록번호]]) -> 0 | E3: B2 | F3: 12408083 | G3: 2025.09.02 | H3: LG ELECTRONICS INC. | M3: The present disclosure relates to a method performed by a non-access point (AP) station (STA) multi-link device (MLD) of a wireless LAN system, the method comprising the steps of: transmitting, through a first link, a negotiation frame including first maximum number of spatial stream (NSS) information to an AP MLD; and receiving a negotiation response frame from the AP MLD through the first link. | N3: BRYAN CAVE LEIGHTON PAISNER LLP | O3: Insun Jang|Jeongki Kim|Jinsoo Choi|Namyeong Kim|Suhwook Kim|Sungjin Park|Taewon Song | P3: =COUNTA(_xlfn.TEXTSPLIT(표1_3[[#This Row],[발명자]], "|")) -> 7 | Q3: =1/표1_3[[#This Row],[발명자수]] -> 0.14285714 | R3: =300*표1_3[[#This Row],[반영비율]] -> 42.857143
A4: 4 | B4: US | C4: Dynamic configuration of multi-link function in wireless LAN system | D4: =COUNTIF(Sheet2!I:I, 표1_3[[#This Row],[등록번호]]) -> 0 | E4: B2 | F4: 12389478 | G4: 2025.08.12 | H4: LG Electronics Inc. | I4: PCT/KR2021/008181 | J4: 20210629 | K4: WO2022005167 | L4: 2022.01.06 | M4: In a wireless local area network (LAN) system, a transmission MLD may include a first station (STA) and a second STA, which operate in a first link and a second link, respectively. The transmission MLD may transmit, to a reception MLD, a connection request frame including capability information related to whether a restricted basic service set (BSS) mode is supported and information related to use of the restricted BSS mode. The information related to the use of the restricted BSS mode may include first information related to an STA (among STAs in the transmission MLD) which operating in the restricted BSS mode, in which monitoring for signal reception (by the STA operating in the restricted BSS from an STA not operating in the restricted BSS mode) is performed based on acquisition of information indicating reception of a signal. The transmission MLD may receive a connection response frame from the reception MLD. | N4: Fish & Richardson P.C. | O4: Namyeong Kim|Jeongki Kim|Jinsoo Choi|Taewon Song|Insun Jang | P4: =COUNTA(_xlfn.TEXTSPLIT(표1_3[[#This Row],[발명자]], "|")) -> 5 | Q4: =1/표1_3[[#This Row],[발명자수]] -> 0.2 | R4: =300*표1_3[[#This Row],[반영비율]] -> 60
A5: 3 | B5: US | C5: Link deactivation in multi-link | D5: =COUNTIF(Sheet2!I:I, 표1_3[[#This Row],[등록번호]]) -> 0 | E5: B2 | F5: 12389493 | G5: 2025.08.12 | H5: LG ELECTRONICS INC. | I5: PCT/KR2020/014772 | J5: 20201028 | K5: WO2021085995 | L5: 2021.05.06 | M5: In a Wireless Local Area Network system, a reception device can receive information about link deactivation, and deactivate a link. The proposed method includes receiving a physical protocol data unit (PPDU) including a first control field in a first link. In the method, the first control field may include information related to disablement of the first link and information on a time point at which the first link is disabled. The proposed method further includes disabling the first link based on the first control field. | N5: LEE, HONG, DEGERMAN, KANG & WAIMEY | O5: Insun Jang|Jeongki Kim|Jinsoo Choi|Suhwook Kim|Sungjin Park|Taewon Song | P5: =COUNTA(_xlfn.TEXTSPLIT(표1_3[[#This Row],[발명자]], "|")) -> 6 | Q5: =1/표1_3[[#This Row],[발명자수]] -> 0.16666667 | R5: =300*표1_3[[#This Row],[반영비율]] -> 50
A6: 5 | B6: US | C6: Reuse of space in multi-ap system | D6: =COUNTIF(Sheet2!I:I, 표1_3[[#This Row],[등록번호]]) -> 0 | E6: B2 | F6: 12376042 | G6: 2025.07.29 | H6: LG ELECTRONICS INC. | I6: PCT/KR2021/000007 | J6: 20210104 | K6: WO2021172732 | L6: 2021.09.02 | M6: A method performed by a sharing access point (AP) of a wireless local area network (LAN) system may comprise the steps of: transmitting, to a shared AP, a first station (STA) list and a first measurement notification frame which requests measurement of received signal strength indicators (RSSIs) of signals transmitted from first STAs included in the first STA list; transmitting, to each of the first STAs, a request frame which requests information related to transmission power of the signals transmitted by the first STAs; receiving a report frame including the information related to the transmission power from each of the first STAs; transmitting a multi-AP transmission trigger frame to the shared AP; and transmitting data to each of the first STAs. | N6: LEE, HONG, DEGERMAN, KANG & WAIMEY | O6: Sungjin Park|Jeongki Kim|Jinsoo Choi|Namyeong Kim|Taewon Song|Insun Jang | P6: =COUNTA(_xlfn.TEXTSPLIT(표1_3[[#This Row],[발명자]], "|")) -> 6 | Q6: =1/표1_3[[#This Row],[발명자수]] -> 0.16666667 | R6: =300*표1_3[[#This Row],[반영비율]] -> 50
A7: 6 | B7: US | C7: Technique for performing multi-link communication in wireless communication system | D7: =COUNTIF(Sheet2!I:I, 표1_3[[#This Row],[등록번호]]) -> 0 | E7: B2 | F7: 12369122 | G7: 2025.07.22 | H7: LG ELECTRONICS INC. | I7: PCT/KR2021/000316 | J7: 20210111 | K7: WO2021141467 | L7: 2021.07.15 | M7: According to various embodiments, a multi-link device (MLD) may transmit, to an access point (AP), a request frame for activating a power saving mechanism (PSM). The multi-link device may receive a response frame for activating the PSM. The multi-link device may activate the PSM in at least one of a first link or the second link on the basis of the response frame. | N7: LEE, HONG, DEGERMAN, KANG & WAIMEY | O7: Namyeong Kim|Jeongki Kim|Jinsoo Choi|Suhwook Kim|Sungjin Park|Taewon Song|Insun Jang | P7: =COUNTA(_xlfn.TEXTSPLIT(표1_3[[#This Row],[발명자]], "|")) -> 7 | Q7: =1/표1_3[[#This Row],[발명자수]] -> 0.14285714 | R7: =300*표1_3[[#This Row],[반영비율]] -> 42.857143
A8: 7 | B8: US | C8: Technique for performing multilink communication in wireless communication system | D8: =COUNTIF(Sheet2!I:I, 표1_3[[#This Row],[등록번호]]) -> 0 | E8: B2 | F8: 12356479 | G8: 2025.07.08 | H8: LG ELECTRONICS INC. | I8: PCT/KR2020/017460 | J8: 20201202 | K8: WO2021112558 | L8: 2021.06.10 | M8: According to various embodiments, a multi-link device (MLD) including a first STA and a second STA can receive a DL PPDU through a first link. The multi-link device can set the state of the second STA to be a doze state during the duration of the DL PPDU. The multi-link device can transmit an ACK frame through the first link in response to the DL PPDU. The multilink device can set the state of the second STA to be an awake state during the duration of the ACK frame. | N8: LEE, HONG, DEGERMAN, KANG & WAIMEY | O8: Namyeong Kim|Jeongki Kim|Jinsoo Choi|Suhwook Kim|Sungjin Park|Taewon Song|Insun Jang | P8: =COUNTA(_xlfn.TEXTSPLIT(표1_3[[#This Row],[발명자]], "|")) -> 7 | Q8: =1/표1_3[[#This Row],[발명자수]] -> 0.14285714 | R8: =300*표1_3[[#This Row],[반영비율]] -> 42.857143
A9: 8 | B9: US | C9: Multi-link setup in wireless communication system | D9: =COUNTIF(Sheet2!I:I, 표1_3[[#This Row],[등록번호]]) -> 0 | E9: B2 | F9: 12342403 | G9: 2025.06.24 | H9: LG Electronics Inc. | M9: In a wireless local area network (WLAN) system, an STA MLD may include a first STA and a second STA, wherein the first STA operates on a first link, and the second STA operates on a second link. The STA MLD may transmit an association request frame to an access point (AP) MLD. The association request frame may include capability information of a requesting STA, which requests to be associated with the AP MLD, among STAs included in the STA MLD and information related to a request link, to with which a request to be associated is transmitted by the requesting STAs. The STA MLD may receive an association response frame from the AP MLD. The association response frame may include capability information of an AP that operates in a link, an association with which is accepted by the AP MLD, among the request links. | N9: Fish & Richardson P.C. | O9: Insun Jang|Jeongki Kim|Jinsoo Choi|Namyeong Kim|Taewon Song|Sunhee Baek | P9: =COUNTA(_xlfn.TEXTSPLIT(표1_3[[#This Row],[발명자]], "|")) -> 6 | Q9: =1/표1_3[[#This Row],[발명자수]] -> 0.16666667 | R9: =300*표1_3[[#This Row],[반영비율]] -> 50
A10: 10 | B10: US | C10: Method for performing multi-link communication in wireless communication system | D10: =COUNTIF(Sheet2!I:I, 표1_3[[#This Row],[등록번호]]) -> 0 | E10: B2 | F10: 12336031 | G10: 2025.06.17 | H10: LG ELECTRONICS INC. | I10: PCT/KR2020/017459 | J10: 20201202 | K10: WO2021112557 | L10: 2021.06.10 | M10: According to various embodiments, a multi-link device (MLD) may transmit, to an AP, a request frame for changing a primary link. On the basis of the request frame, the MLD may receive a response frame from the AP. On the basis of the response frame, the MLD may determine whether to change the primary link. | N10: LEE, HONG, DEGERMAN, KANG & WAIMEY | O10: Namyeong Kim|Jeongki Kim|Jinsoo Choi|Suhwook Kim|Sungjin Park|Taewon Song|Insun Jang | P10: =COUNTA(_xlfn.TEXTSPLIT(표1_3[[#This Row],[발명자]], "|")) -> 7 | Q10: =1/표1_3[[#This Row],[발명자수]] -> 0.14285714 | R10: =300*표1_3[[#This Row],[반영비율]] -> 42.857143
A11: 9 | B11: US | C11: Technique for performing multi-link communication in wireless communication system | D11: =COUNTIF(Sheet2!I:I, 표1_3[[#This Row],[등록번호]]) -> 0 | E11: B2 | F11: 12336032 | G11: 2025.06.17 | H11: LG ELECTRONICS INC. | I11: PCT/KR2021/002078 | J11: 20210218 | K11: WO2021167376 | L11: 2021.08.26 | M11: According to various embodiments, a multi-link device (MLD) operating in a plurality of links may transmit a first request frame for requesting information on the plurality of links. The multi-link device may receive a first response frame on the basis of the first request frame. The first response frame may include information on a ratio of stations (STAs) using a first link as an anchor link, and information on a ratio of STAs using a second link as an anchor link. | N11: BRYAN CAVE LEIGHTON PAISNER LLP | O11: Namyeong Kim|Jeongki Kim|Jinsoo Choi|Sungjin Park|Taewon Song|Insun Jang | P11: =COUNTA(_xlfn.TEXTSPLIT(표1_3[[#This Row],[발명자]], "|")) -> 6 | Q11: =1/표1_3[[#This Row],[발명자수]] -> 0.16666667 | R11: =300*표1_3[[#This Row],[반영비율]] -> 50
A12: 11 | B12: US | C12: Transmission power in multi-AP transmission using space reuse | D12: =COUNTIF(Sheet2!I:I, 표1_3[[#This Row],[등록번호]]) -> 0 | E12: B2 | F12: 12328686 | G12: 2025.06.10 | H12: LG ELECTRONICS INC. | I12: PCT/KR2021/000194 | J12: 20210107 | K12: WO2021177587 | L12: 2021.09.10 | M12: In a wireless local area network (LAN) system, a shared AP may determine PPDU transmission power to be transmitted to an STA on the basis of an ARIL of the STA, transmission power of a signal transmitted to the STA by a sharing AP, and an RSSI of a signal received from the sharing AP by the STA. | N12: Bryan Cave Leighton Paisner LLP | O12: Sungjin Park|Jeongki Kim|Jinsoo Choi|Namyeong Kim|Taewon Song|Insun Jang | P12: =COUNTA(_xlfn.TEXTSPLIT(표1_3[[#This Row],[발명자]], "|")) -> 6 | Q12: =1/표1_3[[#This Row],[발명자수]] -> 0.16666667 | R12: =300*표1_3[[#This Row],[반영비율]] -> 50
A13: 13 | B13: US | C13: Trigger-based data transmission | D13: =COUNTIF(Sheet2!I:I, 표1_3[[#This Row],[등록번호]]) -> 0 | E13: B2 | F13: 12317317 | G13: 2025.05.27 | H13: LG ELECTRONICS INC. | I13: PCT/KR2021/001692 | J13: 20210209 | K13: WO2021162399 | L13: 2021.08.19 | M13: In a wireless local area network (WLAN) system, an STA performs CCA on resources allocated thereto via a trigger frame from an AP and can transmit a TB PPDU via an idle channel among the allocated resources on the basis of the result of the CCA, wherein the PHY of the TB PPDU may include information about the result of the CCA. | N13: LEE, HONG, DEGERMAN, KANG & WAIMEY | O13: Insun Jang|Jeongki Kim|Jinsoo Choi|Suhwook Kim|Namyeong Kim|Sungjin Park|Taewon Song | P13: =COUNTA(_xlfn.TEXTSPLIT(표1_3[[#This Row],[발명자]], "|")) -> 7 | Q13: =1/표1_3[[#This Row],[발명자수]] -> 0.14285714 | R13: =300*표1_3[[#This Row],[반영비율]] -> 42.857143
A14: 12 | B14: US | C14: Method and device for acquiring information on links between MLDs in wireless LAN system | D14: =COUNTIF(Sheet2!I:I, 표1_3[[#This Row],[등록번호]]) -> 0 | E14: B2 | F14: 12317351 | G14: 2025.05.27 | H14: LG ELECTRONICS INC. | I14: PCT/KR2021/012103 | J14: 20210907 | K14: WO2022050814 | L14: 2022.03.10 | M14: Proposed are a method and device for acquiring information on links between MLDs in a wireless LAN system. Specifically, a receiving MLD transmits a probe request frame to a transmitting MLD through a first link. The receiving MLD receives a probe response frame from the transmitting MLD through the first link. The transmitting MLD comprises: a first transmitting STA operating in the first link; a second transmitting STA operating in a second link; and a third transmitting STA operating in a third link. The receiving MLD comprises a first receiving STA operating in the first link. When the first receiving STA requests for information on the second and third links, the probe request frame includes link identifiers for the second and third links. When the first receiving STA requests for information on all the links, the probe request frame does not include link identifiers for all the links. | N14: LEE, HONG, DEGERMAN, KANG & WAIMEY | O14: Namyeong Kim|Jeongki Kim|Jinsoo Choi|Taewon Song|Insun Jang | P14: =COUNTA(_xlfn.TEXTSPLIT(표1_3[[#This Row],[발명자]], "|")) -> 5 | Q14: =1/표1_3[[#This Row],[발명자수]] -> 0.2 | R14: =300*표1_3[[#This Row],[반영비율]] -> 60
A15: 14 | B15: US | C15: HARQ operations at PHY layer level | D15: =COUNTIF(Sheet2!I:I, 표1_3[[#This Row],[등록번호]]) -> 0 | E15: B2 | F15: 12309099 | G15: 2025.05.20 | H15: LG ELECTRONICS INC. | I15: PCT/KR2020/011417 | J15: 20200826 | K15: WO2021066326 | L15: 2021.04.08 | M15: An AP and a STA can perform a PHY-level HARQ operation in a wireless local area network system, and the AP can transmit resource allocation information about a PHY-level feedback frame to be transmitted by a plurality of STAs. The AP can receive a plurality of HARQ feedback frames from a plurality of STAs. The plurality of HARQ feedback frames are PHY layer signals. The resource allocation information can include information related to a tone set and a symbol from which transmission of the plurality of HARQ feedback frames are started. | N15: BRYAN CAVE LEIGHTON PAISNER LLP | O15: Taewon Song|Jeongki Kim|Jinsoo Choi|Suhwook Kim|Jinmin Kim|Sungjin Park|Insun Jang | P15: =COUNTA(_xlfn.TEXTSPLIT(표1_3[[#This Row],[발명자]], "|")) -> 7 | Q15: =1/표1_3[[#This Row],[발명자수]] -> 0.14285714 | R15: =300*표1_3[[#This Row],[반영비율]] -> 42.857143
A16: 16 | B16: US | C16: Shared AP selection in multi-AP system | D16: =COUNTIF(Sheet2!I:I, 표1_3[[#This Row],[등록번호]]) -> 0 | E16: B2 | F16: 12302213 | G16: 2025.05.13 | H16: LG ELECTRONICS INC. | I16: PCT/KR2020/012138 | J16: 20200909 | K16: WO2021075725 | L16: 2021.04.22 | M16: In a wireless local area network (LAN) system, a sharing access point (AP): receives, from a first AP, basic service set (BSS) information of the first AP; receives, from a second AP, BSS information of the second AP; receives, from a station (STA), a link report signal including link quality information about the link between the first AP and the STA and link quality information about the link between the second AP and the STA; and selects the first AP as a shared AP on the basis of first and second capability information and the link quality information. | N16: LEE, HONG, DEGERMAN, KANG & WAIMEY | O16: Sungjin Park|Jeongki Kim|Jinsoo Choi|Suhwook Kim|Taewon Song|Insun Jang | P16: =COUNTA(_xlfn.TEXTSPLIT(표1_3[[#This Row],[발명자]], "|")) -> 6 | Q16: =1/표1_3[[#This Row],[발명자수]] -> 0.16666667 | R16: =300*표1_3[[#This Row],[반영비율]] -> 50
A17: 15 | B17: US | C17: Technique for performing multi-link communication in wireless communication system | D17: =COUNTIF(Sheet2!I:I, 표1_3[[#This Row],[등록번호]]) -> 0 | E17: B2 | F17: 12302248 | G17: 2025.05.13 | H17: LG ELECTRONICS INC. | I17: PCT/KR2020/017458 | J17: 20201202 | K17: WO2021112556 | L17: 2021.06.10 | M17: According to various embodiments, a multi-link device including a first STA and a second STA may receive, via the first STA, at least one PPDU within a transmission opportunity (TXOP) configured in a first link. While the at least one PPDU is received, the state of the second STA may be set to a doze state. The multi-link device may receive, via the first STA, a first control frame for the truncation of the TXOP. The multi-link device may change the state of the second STA from the doze state to an awake state on the basis of the first control frame. | N17: LEE, HONG, DEGERMAN, KANG & WAIMEY | O17: Namyeong Kim|Jeongki Kim|Jinsoo Choi|Suhwook Kim|Sungjin Park|Taewon Song|Insun Jang | P17: =COUNTA(_xlfn.TEXTSPLIT(표1_3[[#This Row],[발명자]], "|")) -> 7 | Q17: =1/표1_3[[#This Row],[발명자수]] -> 0.14285714 | R17: =300*표1_3[[#This Row],[반영비율]] -> 42.857143
A18: 17 | B18: US | C18: Technique for performing multi-link communication in wireless communication system | D18: =COUNTIF(Sheet2!I:I, 표1_3[[#This Row],[등록번호]]) -> 0 | E18: B2 | F18: 12289685 | G18: 2025.04.29 | H18: LG ELECTRONICS INC. | I18: PCT/KR2021/000315 | J18: 20210111 | K18: WO2021141466 | L18: 2021.07.15 | M18: According to various embodiments, a multi-link device including a first STA and a second STA may receive a first PPDU by means of the first STA. The PPDU may include information about traffic buffered in the second STA operating in a second link. In response to the first PPDU, the multi-link device may change the second STA from a doze state to an awake state, and transmit information about the state of the second STA by means of the second STA. | N18: LEE, HONG, DEGERMAN, KANG & WAIMEY | O18: Namyeong Kim|Jeongki Kim|Jinsoo Choi|Suhwook Kim|Sungjin Park|Taewon Song|Insun Jang | P18: =COUNTA(_xlfn.TEXTSPLIT(표1_3[[#This Row],[발명자]], "|")) -> 7 | Q18: =1/표1_3[[#This Row],[발명자수]] -> 0.14285714 | R18: =300*표1_3[[#This Row],[반영비율]] -> 42.857143
A19: 18 | B19: US | C19: Multi-link channel access | D19: =COUNTIF(Sheet2!I:I, 표1_3[[#This Row],[등록번호]]) -> 0 | E19: B2 | F19: 12279303 | G19: 2025.04.15 | H19: LG ELECTRONICS INC. | I19: PCT/KR2020/015340 | J19: 20201104 | K19: WO2021091231 | L19: 2021.05.14 | M19: In a wireless local area network (WLAN) system, a transmitting multi-link device (MLD) may defer the transmission of a PPDU on a first link, even if a back-off counter of a non-primary link reaches zero, as long as a back-off counter of a primary link does not reach zero. When the transmission of the PPDU is deferred, the back-off counter may be kept at zero. | N19: LEE, HONG, DEGERMAN, KANG & WAIMEY | O19: Insun Jang|Jeongki Kim|Jinsoo Choi|Suhwook Kim|Namyeong Kim|Sungjin Park|Taewon Song | P19: =COUNTA(_xlfn.TEXTSPLIT(표1_3[[#This Row],[발명자]], "|")) -> 7 | Q19: =1/표1_3[[#This Row],[발명자수]] -> 0.14285714 | R19: =300*표1_3[[#This Row],[반영비율]] -> 42.857143
A20: 19 | B20: US | C20: Method for performing multi-link communication in wireless communication system | D20: =COUNTIF(Sheet2!I:I, 표1_3[[#This Row],[등록번호]]) -> 0 | E20: B2 | F20: 12273945 | G20: 2025.04.08 | H20: LG ELECTRONICS INC. | I20: PCT/KR2021/002686 | J20: 20210304 | K20: WO2021177749 | L20: 2021.09.10 | M20: According to various embodiments, a multi-link device (MLD) operating in a plurality of links including a first link can transmit a request frame to a first AP of an AP MLD through a first STA (station), wherein the request frame includes an information field for requesting every element included in an element set designated for a second link. The MLD can, on the basis of the request frame, receive every element included in the element set designated for the second link. | N20: BRYAN CAVE LEIGHTON PAISNER LLP | O20: Namyeong Kim|Jeongki Kim|Jinsoo Choi|Sungjin Park|Taewon Song|Insun Jang | P20: =COUNTA(_xlfn.TEXTSPLIT(표1_3[[#This Row],[발명자]], "|")) -> 6 | Q20: =1/표1_3[[#This Row],[발명자수]] -> 0.16666667 | R20: =300*표1_3[[#This Row],[반영비율]] -> 50
A21: 20 | B21: US | C21: Signaling for multi-link transmission | D21: =COUNTIF(Sheet2!I:I, 표1_3[[#This Row],[등록번호]]) -> 0 | E21: B2 | F21: 12267900 | G21: 2025.04.01 | H21: LG ELECTRONICS INC. | I21: PCT/KR2021/000273 | J21: 20210108 | K21: WO2021141449 | L21: 2021.07.15 | M21: In a wireless local area network system, a multi-link device (MLD) may transmit a multi-link element including a number-of-links field and a link present field indicating whether the number-of-links field exists. The multi-link element further includes a multi-link control field, a common information field, and a link information field. The number-of-links field may be included in the multi-link control field. | N21: LEE, HONG, DEGERMAN, KANG & WAIMEY | O21: Insun Jang|Jeongki Kim|Jinsoo Choi|Suhwook Kim|Namyeong Kim|Sungjin Park|Taewon Song | P21: =COUNTA(_xlfn.TEXTSPLIT(표1_3[[#This Row],[발명자]], "|")) -> 7 | Q21: =1/표1_3[[#This Row],[발명자수]] -> 0.14285714 | R21: =300*표1_3[[#This Row],[반영비율]] -> 42.857143
A22: 21 | B22: US | C22: Ack transmission using multilink | D22: =COUNTIF(Sheet2!I:I, 표1_3[[#This Row],[등록번호]]) -> 1 | E22: B2 | F22: 12250076 | G22: 2025.03.11 | H22: LG ELECTRONICS INC. | I22: PCT/KR2020/010891 | J22: 20200814 | K22: WO2021125491 | L22: 2021.06.24 | M22: In a wireless local area network system, a receiving device may receive a Block Acknowledgment Request (BAR) frame including information related to a link for which an ACK is requested, and transmit a Block ACK (BA) frame on the basis of the BAR frame. The receiving device is a Multi-Link Device (MLD), which supports communication over multiple links. Each link of the multiple links can be configured based on 2.4 GHz band, 5 GHz band, and/or 6 GHz band defined in a conventional wireless local area network system. | N22: LEE, HONG, DEGERMAN, KANG & WAIMEY | O22: Taewon Song|Jeongki Kim|Jinsoo Choi|Suhwook Kim|Namyeong Kim|Sungjin Park|Insun Jang | P22: =COUNTA(_xlfn.TEXTSPLIT(표1_3[[#This Row],[발명자]], "|")) -> 7 | Q22: =1/표1_3[[#This Row],[발명자수]] -> 0.14285714 | R22: =300*표1_3[[#This Row],[반영비율]] -> 42.857143
A23: 22 | B23: US | C23: Multi-link channel access | D23: =COUNTIF(Sheet2!I:I, 표1_3[[#This Row],[등록번호]]) -> 1 | E23: B2 | F23: 12238761 | G23: 2025.02.25 | H23: LG ELECTRONICS INC. | M23: In a wireless local area network (WLAN) system, a transmitting multi-link device (MLD) may defer the transmission of a PPDU on a first link, even if a back-off counter of a non-primary link reaches zero, as long as a back-off counter of a primary link does not reach zero. When the transmission of the PPDU is deferred, the back-off counter may be kept at zero. | N23: LEE, HONG, DEGERMAN, KANG & WAIMEY | O23: Insun Jang|Jeongki Kim|Jinsoo Choi|Suhwook Kim|Namyeong Kim|Sungjin Park|Taewon Song | P23: =COUNTA(_xlfn.TEXTSPLIT(표1_3[[#This Row],[발명자]], "|")) -> 7 | Q23: =1/표1_3[[#This Row],[발명자수]] -> 0.14285714 | R23: =300*표1_3[[#This Row],[반영비율]] -> 42.857143
A24: 24 | B24: US | C24: Method for performing multi-link communication in wireless communication system | D24: =COUNTIF(Sheet2!I:I, 표1_3[[#This Row],[등록번호]]) -> 1 | E24: B2 | F24: 12219638 | G24: 2025.02.04 | H24: LG ELECTRONICS INC. | M24: According to various embodiments, a multi-link device (MLD) operating in a plurality of links including a first link can transmit a request frame to a first AP of an AP MILD through a first STA (station), wherein the request frame includes an information field for requesting every element included in an element set designated for a second link. The MILD can, on the basis of the request frame, receive every element included in the element set designated for the second link. | N24: BRYAN CAVE LEIGHTON PAISNER LLP | O24: Namyeong Kim|Jeongki Kim|Jinsoo Choi|Sungjin Park|Taewon Song|Insun Jang | P24: =COUNTA(_xlfn.TEXTSPLIT(표1_3[[#This Row],[발명자]], "|")) -> 6 | Q24: =1/표1_3[[#This Row],[발명자수]] -> 0.16666667 | R24: =300*표1_3[[#This Row],[반영비율]] -> 50
A25: 23 | B25: US | C25: Method for changing channel in multi-links | D25: =COUNTIF(Sheet2!I:I, 표1_3[[#This Row],[등록번호]]) -> 1 | E25: B2 | F25: 12219644 | G25: 2025.02.04 | H25: LG ELECTRONICS INC. | I25: PCT/KR2020/011838 | J25: 20200903 | K25: WO2021049817 | L25: 2021.03.18 | M25: Presented are a method by which a transmitting device performs channel switching between multi-links in a wireless local area network (LAN) system, and a device. Particularly, the method comprises the steps of: transmitting multi-link channel switching capability information to a receiving device, wherein the multi-link channel switching capability information includes information related to whether the transmitting device can perform channel changing between multi-link channels; transmitting a physical protocol data unit (PPDU) to the receiving device through a first link; transmitting a multi-link channel change signal to the receiving device through the first link; and transmitting the PPDU to the receiving device through a second link. | N25: LEE, HONG, DEGERMAN, KANG & WAIMEY | O25: Insun Jang|Jeongki Kim|Jinsoo Choi|Suhwook Kim|Sungjin Park|Taewon Song | P25: =COUNTA(_xlfn.TEXTSPLIT(표1_3[[#This Row],[발명자]], "|")) -> 6 | Q25: =1/표1_3[[#This Row],[발명자수]] -> 0.16666667 | R25: =300*표1_3[[#This Row],[반영비율]] -> 50
A26: 25 | B26: US | C26: Transmission of capability information about link | D26: =COUNTIF(Sheet2!I:I, 표1_3[[#This Row],[등록번호]]) -> 1 | E26: B2 | F26: 12200544 | G26: 2025.01.14 | H26: LG ELECTRONICS INC. | I26: PCT/KR2020/018878 | J26: 20201222 | K26: WO2021162234 | L26: 2021.08.19 | M26: The present disclosure relates to a method performed by a non-access point (AP) station (STA) multi-link device (MLD) of a wireless LAN system, the method comprising the steps of: transmitting, through a first link, a negotiation frame including first maximum number of spatial stream (NSS) information to an AP MLD; and receiving a negotiation response frame from the AP MLD through the first link. | N26: BRYAN CAVE LEIGHTON PAISNER LLP | O26: Insun Jang|Jeongki Kim|Jinsoo Choi|Namyeong Kim|Suhwook Kim|Sungjin Park|Taewon Song | P26: =COUNTA(_xlfn.TEXTSPLIT(표1_3[[#This Row],[발명자]], "|")) -> 7 | Q26: =1/표1_3[[#This Row],[발명자수]] -> 0.14285714 | R26: =300*표1_3[[#This Row],[반영비율]] -> 42.857143
A27: 26 | B27: US | C27: Technique for performing multi-link communication in wireless communication system | D27: =COUNTIF(Sheet2!I:I, 표1_3[[#This Row],[등록번호]]) -> 1 | E27: B2 | F27: 12192875 | G27: 2025.01.07 | H27: LG ELECTRONICS INC. | I27: PCT/KR2021/003221 | J27: 20210316 | K27: WO2021187858 | L27: 2021.09.23 | M27: According to various embodiments, a multi-link device (MLD) operating in a plurality of links can receive a PPDU through a first link from among the plurality of links. The PPU can include a first information field related to a second link that is differentiated from the first link. The first information field related to a second link can include a second information field related to a link identifier of a second link and a third information field related to whether all pieces of element information related to a second link is included in the PPDU. | N27: BRYAN CAVE LEIGHTON PAISNER LLP | O27: Namyeong Kim|Jeongki Kim|Jinsoo Choi|Sungjin Park|Taewon Song|Insun Jang | P27: =COUNTA(_xlfn.TEXTSPLIT(표1_3[[#This Row],[발명자]], "|")) -> 6 | Q27: =1/표1_3[[#This Row],[발명자수]] -> 0.16666667 | R27: =300*표1_3[[#This Row],[반영비율]] -> 50
A28: 27 | B28: US | C28: NACK frame for HARQ operation | D28: =COUNTIF(Sheet2!I:I, 표1_3[[#This Row],[등록번호]]) -> 1 | E28: B2 | F28: 12184426 | G28: 2024.12.31 | H28: LG ELECTRONICS INC. | I28: PCT/KR2020/005100 | J28: 20200416 | K28: WO2020222446 | L28: 2020.11.05 | M28: In a wireless local area network (LAN) system, a transmission station (STA) may transmit, to a receiving STA, a PHY protocol data unit (PPDU) including a first redundancy version of transmission data. On the basis of whether an acknowledgement (ACK) or negative ACK (NACK) frame is received within a threshold time, the transmission STA may determine a second redundancy version of the transmission data to be retransmitted. | N28: BRYAN CAVE LEIGHTON PAISNER LLP | O28: Taewon Song|Kiseon Ryu|Jeongki Kim|Jinsoo Choi|Suhwook Kim|Insun Jang | P28: =COUNTA(_xlfn.TEXTSPLIT(표1_3[[#This Row],[발명자]], "|")) -> 6 | Q28: =1/표1_3[[#This Row],[발명자수]] -> 0.16666667 | R28: =300*표1_3[[#This Row],[반영비율]] -> 50
A29: 28 | B29: US | C29: Mapping of TID and link in multi-link | D29: =COUNTIF(Sheet2!I:I, 표1_3[[#This Row],[등록번호]]) -> 1 | E29: B2 | F29: 12177914 | G29: 2024.12.24 | H29: LG ELECTRONICS INC. | I29: PCT/KR2020/008060 | J29: 20200622 | K29: WO2021002617 | L29: 2021.01.07 | M29: In a wireless local area network (LAN) system, a station (STA) may transmit a first physical protocol data unit (PPDU) including information indicating that a first traffic identifier (TID) is mapped to a first link and a second TID is mapped to a second link. The STA may transmit traffic pertaining to the first TID through only the first link, and traffic pertaining to the second TID through only the second link. | N29: LEE, HONG, DEGERMAN, KANG & WAIMEY | O29: Insun Jang|Jeongki Kim|Jinsoo Choi|Suhwook Kim|Sungjin Park|Taewon Song | P29: =COUNTA(_xlfn.TEXTSPLIT(표1_3[[#This Row],[발명자]], "|")) -> 6 | Q29: =1/표1_3[[#This Row],[발명자수]] -> 0.16666667 | R29: =300*표1_3[[#This Row],[반영비율]] -> 50
A30: 29 | B30: US | C30: Resumption of PHY-level HARQ operation | D30: =COUNTIF(Sheet2!I:I, 표1_3[[#This Row],[등록번호]]) -> 0 | E30: B2 | F30: 12166584 | G30: 2024.12.10 | H30: LG ELECTRONICS INC. | I30: PCT/KR2020/009936 | J30: 20200728 | K30: WO2021033938 | L30: 2021.02.25 | M30: The present specification proposes a method for resuming a PHY-level HARQ operation in a wireless local area network (WLAN) system. The method may include transmitting a resume signal including information related to resumption of hybrid automatic repeat request (HARQ) retransmission. The method may include transmitting a physical protocol data unit (PPDU) after transmitting the resume signal. The PPDU and the resume signal may be transmitted in different transmission opportunities (TXOPs). | N30: BRYAN CAVE LEIGHTON PAISNER LLP | O30: Taewon Song|Jeongki Kim|Jinsoo Choi|Suhwook Kim|Jinmin Kim|Sungjin Park|Insun Jang | P30: =COUNTA(_xlfn.TEXTSPLIT(표1_3[[#This Row],[발명자]], "|")) -> 7 | Q30: =1/표1_3[[#This Row],[발명자수]] -> 0.14285714 | R30: =300*표1_3[[#This Row],[반영비율]] -> 42.857143
A31: 30 | B31: US | C31: MPDU padding for HARQ operation | D31: =COUNTIF(Sheet2!I:I, 표1_3[[#This Row],[등록번호]]) -> 1 | E31: B2 | F31: 12150098 | G31: 2024.11.19 | H31: LG ELECTRONICS INC. | I31: PCT/KR2020/004629 | J31: 20200406 | K31: WO2020209558 | L31: 2020.10.15 | M31: In a wireless local area network system, a station (STA) generates a physical (PHY) protocol data unit (PPDU) including at least one subframe and information related to a subframe length, wherein the subframe may include a medium access control (MAC) protocol data unit (MPDU) and a padding bit. The length of the padding bit may be determined such that the length of the subframes is an integer multiple of a codeword length. The information related to the subframe length may be information on the number of codewords related to the subframe length. A step in which the STA transmits the PPDU may be comprised. | N31: BRYAN CAVE LEIGHTON PAISNER LLP | O31: Taewon Song|Kiseon Ryu|Jeongki Kim|Jinsoo Choi|Suhwook Kim|Jinmin Kim|Insun Jang | P31: =COUNTA(_xlfn.TEXTSPLIT(표1_3[[#This Row],[발명자]], "|")) -> 7 | Q31: =1/표1_3[[#This Row],[발명자수]] -> 0.14285714 | R31: =300*표1_3[[#This Row],[반영비율]] -> 42.857143
A32: 31 | B32: US | C32: Method for performing multi-link communication in wireless communication system | D32: =COUNTIF(Sheet2!I:I, 표1_3[[#This Row],[등록번호]]) -> 1 | E32: B2 | F32: 12133162 | G32: 2024.10.29 | H32: LG ELECTRONICS INC. | I32: PCT/KR2021/002737 | J32: 20210305 | K32: WO2021177774 | L32: 2021.09.10 | M32: According to various embodiments, a multi-link device (MLD) operating in multiple links including a first link may transmit, through a first station (STA) and to a first AP of an AP multi-link device, a request frame including an information field for requesting at least one element related to a second link. The multi-link device may receive at least one element related to the second link on the basis of the request frame. | N32: BRYAN CAVE LEIGHTON PAISNER LLP | O32: Namyeong Kim|Jeongki Kim|Jinsoo Choi|Sungjin Park|Taewon Song|Insun Jang | P32: =COUNTA(_xlfn.TEXTSPLIT(표1_3[[#This Row],[발명자]], "|")) -> 6 | Q32: =1/표1_3[[#This Row],[발명자수]] -> 0.16666667 | R32: =300*표1_3[[#This Row],[반영비율]] -> 50
A33: 33 | B33: US | C33: Multi-link RTS and CTS transmissions | D33: =COUNTIF(Sheet2!I:I, 표1_3[[#This Row],[등록번호]]) -> 0 | E33: B2 | F33: 12120741 | G33: 2024.10.15 | H33: LG ELECTRONICS INC. | I33: PCT/KR2020/018689 | J33: 20201218 | K33: WO2021167223 | L33: 2021.08.26 | M33: In a wireless local area network system, a reception multi-link device (MLD) may not transmit a CTS frame, even if the reception multi-link device receives an RTS frame via a second link, in the case that an STA operating via a first link is a TXOP responder. | N33: BRYAN CAVE LEIGHTON PAISNER LLP | O33: Insun Jang|Jeongki Kim|Jinsoo Choi|Namyeong Kim|Suhwook Kim|Sungjin Park|Taewon Song | P33: =COUNTA(_xlfn.TEXTSPLIT(표1_3[[#This Row],[발명자]], "|")) -> 7 | Q33: =1/표1_3[[#This Row],[발명자수]] -> 0.14285714 | R33: =300*표1_3[[#This Row],[반영비율]] -> 42.857143
A34: 32 | B34: US | C34: Mapping of TID and link in multi-link | D34: =COUNTIF(Sheet2!I:I, 표1_3[[#This Row],[등록번호]]) -> 1 | E34: B2 | F34: 12120763 | G34: 2024.10.15 | H34: LG ELECTRONICS INC. | M34: In a wireless local area network (LAN) system, a station (STA) may transmit a first physical protocol data unit (PPDU) including information indicating that a first traffic identifier (TID) is mapped to a first link and a second TID is mapped to a second link. The STA may transmit traffic pertaining to the first TID through only the first link, and traffic pertaining to the second TID through only the second link. | N34: LEE, HONG, DEGERMAN, KANG & WAIMEY | O34: Insun Jang|Jeongki Kim|Jinsoo Choi|Suhwook Kim|Sungjin Park|Taewon Song | P34: =COUNTA(_xlfn.TEXTSPLIT(표1_3[[#This Row],[발명자]], "|")) -> 6 | Q34: =1/표1_3[[#This Row],[발명자수]] -> 0.16666667 | R34: =300*표1_3[[#This Row],[반영비율]] -> 50
A35: 34 | B35: US | C35: Data sharing in multi-AP system | D35: =COUNTIF(Sheet2!I:I, 표1_3[[#This Row],[등록번호]]) -> 0 | E35: B2 | F35: 12108418 | G35: 2024.10.01 | H35: LG ELECTRONICS INC. | I35: PCT/KR2020/010383 | J35: 20200806 | K35: WO2021045396 | L35: 2021.03.11 | M35: In a wireless local area network system, a shared AP may receive an announcement frame and a data frame from a sharing AP for multi-AP transmission. In the present disclosure, the announcement frame may be transmitted in a broadcasting scheme. The data field of the announcement frame may include an identifier (ID) of the shared AP. The shared AP may receive a data frame from the sharing AP. In the present disclosure, a receiver address (RA) field of the data frame may include an address of the sharing AP. The shared AP may decode the data frame based on the address of the sharing AP included in the RA field of the data frame. | N35: LEE, HONG, DEGERMAN, KANG & WAIMEY | O35: Sungjin Park|Jeongki Kim|Jinsoo Choi|Suhwook Kim|Taewon Song|Insun Jang | P35: =COUNTA(_xlfn.TEXTSPLIT(표1_3[[#This Row],[발명자]], "|")) -> 6 | Q35: =1/표1_3[[#This Row],[발명자수]] -> 0.16666667 | R35: =300*표1_3[[#This Row],[반영비율]] -> 50
A36: 36 | B36: US | C36: Method for performing multi-link communication in wireless communication system | D36: =COUNTIF(Sheet2!I:I, 표1_3[[#This Row],[등록번호]]) -> 1 | E36: B2 | F36: 12089140 | G36: 2024.09.10 | H36: LG ELECTRONICS INC. | M36: According to various embodiments, a multi-link device (MLD) operating in multiple links including a first link may transmit, through a first station (STA) and to a first AP of an AP multi-link device, a request frame including an information field for requesting at least one element related to a second link. The multi-link device may receive at least one element related to the second link on the basis of the request frame. | N36: BRYAN CAVE LEIGHTON PAISNER LLP | O36: Namyeong Kim|Jeongki Kim|Jinsoo Choi|Sungjin Park|Taewon Song|Insun Jang | P36: =COUNTA(_xlfn.TEXTSPLIT(표1_3[[#This Row],[발명자]], "|")) -> 6 | Q36: =1/표1_3[[#This Row],[발명자수]] -> 0.16666667 | R36: =300*표1_3[[#This Row],[반영비율]] -> 50
A37: 35 | B37: US | C37: Multi-link RTS and CTS transmissions | D37: =COUNTIF(Sheet2!I:I, 표1_3[[#This Row],[등록번호]]) -> 1 | E37: B2 | F37: 12089255 | G37: 2024.09.10 | H37: LG ELECTRONICS INC. | M37: In a wireless local area network system, a reception multi-link device (MLD) may not transmit a CTS frame, even if the reception multi-link device receives an RTS frame via a second link, in the case that an STA operating via a first link is a TXOP responder. In detail, the reception MLD may include at least one non-simultaneous transmit and receive (NSTR) link pair. A first STA affiliated with the MLD may determine to respond with the CTS frame to the RTS frame. The first STA does not respond with the CTS frame based on another STA being a transmission opportunity (TXOP) responder on another link. | N37: BRYAN CAVE LEIGHTON PAISNER LLP | O37: Insun Jang|Jeongki Kim|Jinsoo Choi|Namyeong Kim|Suhwook Kim|Sungjin Park|Taewon Song | P37: =COUNTA(_xlfn.TEXTSPLIT(표1_3[[#This Row],[발명자]], "|")) -> 7 | Q37: =1/표1_3[[#This Row],[발명자수]] -> 0.14285714 | R37: =300*표1_3[[#This Row],[반영비율]] -> 42.857143
A38: 38 | B38: US | C38: Channel access in multi-link | D38: =COUNTIF(Sheet2!I:I, 표1_3[[#This Row],[등록번호]]) -> 1 | E38: B2 | F38: 12082242 | G38: 2024.09.03 | H38: LG ELECTRONICS INC. | I38: PCT/KR2020/014771 | J38: 20201028 | K38: WO2021085994 | L38: 2021.05.06 | M38: A method for a non-simultaneous transmit and receive (non-STR) device in a wireless local area network (LAN) is provided. The non-STR device may support a multi-link communication related to a first link and a second link. The non-STR device may determine whether to transmit a first physical protocol data unit (PPDU), PPDU, based on a channel access result on the first link and a channel access result on the second link. The non-STR device determines not to transmit the first PPDU through the first link and keeps the back-off counter of the first link at zero (0) when a back-off counter of the first link reaches zero (0) and a back-off counter of the second link does not reach zero (0). | N38: LEE, HONG, DEGERMAN, KANG & WAIMEY | O38: Insun Jang|Jeongki Kim|Jinsoo Choi|Suhwook Kim|Namyeong Kim|Sungjin Park|Taewon Song | P38: =COUNTA(_xlfn.TEXTSPLIT(표1_3[[#This Row],[발명자]], "|")) -> 7 | Q38: =1/표1_3[[#This Row],[발명자수]] -> 0.14285714 | R38: =300*표1_3[[#This Row],[반영비율]] -> 42.857143
A39: 37 | B39: US | C39: Method and device for acquiring information on links between MLDS in wireless LAN system | D39: =COUNTIF(Sheet2!I:I, 표1_3[[#This Row],[등록번호]]) -> 1 | E39: B2 | F39: 12082281 | G39: 2024.09.03 | H39: LG ELECTRONICS INC. | M39: Proposed are a method and device for acquiring information on links between MLDs in a wireless LAN system. Specifically, a receiving MLD transmits a probe request frame to a transmitting MLD through a first link. The receiving MLD receives a probe response frame from the transmitting MLD through the first link. The transmitting MLD comprises: a first transmitting STA operating in the first link; a second transmitting STA operating in a second link; and a third transmitting STA operating in a third link. The receiving MLD comprises a first receiving STA operating in the first link. When the first receiving STA requests for information on the second and third links, the probe request frame includes link identifiers for the second and third links. When the first receiving STA requests for information on all the links, the probe request frame does not include link identifiers for all the links. | N39: LEE, HONG, DEGERMAN, KANG & WAIMEY | O39: Namyeong Kim|Jeongki Kim|Jinsoo Choi|Taewon Song|Insun Jang | P39: =COUNTA(_xlfn.TEXTSPLIT(표1_3[[#This Row],[발명자]], "|")) -> 5 | Q39: =1/표1_3[[#This Row],[발명자수]] -> 0.2 | R39: =300*표1_3[[#This Row],[반영비율]] -> 60
A40: 39 | B40: US | C40: Signaling for multi-link transmission | D40: =COUNTIF(Sheet2!I:I, 표1_3[[#This Row],[등록번호]]) -> 1 | E40: B2 | F40: 12058753 | G40: 2024.08.06 | H40: LG ELECTRONICS INC. | M40: In a wireless local area network system, a multi-link device (MLD) may transmit a multi-link element including a number-of-links field and a link present field indicating whether the number-of-links field exists. The multi-link element further includes a multi-link control field, a common information field, and a link information field. The number-of-links field may be included in the multi-link control field. | N40: LEE, HONG, DEGERMAN, KANG & WAIMEY | O40: Insun Jang|Jeongki Kim|Jinsoo Choi|Suhwook Kim|Namyeong Kim|Sungjin Park|Taewon Song | P40: =COUNTA(_xlfn.TEXTSPLIT(표1_3[[#This Row],[발명자]], "|")) -> 7 | Q40: =1/표1_3[[#This Row],[발명자수]] -> 0.14285714 | R40: =300*표1_3[[#This Row],[반영비율]] -> 42.857143
...

Sheet Sheet2
A1: 순번 | B1: 국가 | C1: 발명의 명칭 | D1: 분류 | E1: 출원번호 | F1: 출원일자 | G1: 공개번호 | H1: 공개일자 | I1: 등록번호 | J1: 등록일자 | K1: 공보일자 | L1: 국제출원번호 | M1: 국제출원일자 | N1: 국제공개번호 | O1: 국제공개일자 | P1: 출원인 | Q1: 발명자 | R1: 열4 | S1: 요약 | T1: 열3 | U1: 열1 | V1: 열2
A2: 1 | B2: US | C2: Ack transmission using multilink | D2: B2 | E2: 17757045 | F2: 2020.08.14 | G2: 20220385403 | H2: 2022.12.01 | I2: 12250076 | J2: 2025.03.11 | K2: 12250076 | L2: PCT/KR2020/010891 | M2: 20200814 | N2: WO2021125491 | O2: 2021.06.24 | P2: LG ELECTRONICS INC. | Q2: Taewon Song|Jeongki Kim|Jinsoo Choi|Suhwook Kim|Namyeong Kim|Sungjin Park|Insun Jang | R2: 무선 LAN 시스템에서 수신 장치가 ACK 요청 링크 정보가 포함된 BAR 프레임을 수신하고 이를 기반으로 BA 프레임을 전송하는 기술. 수신 장치는 복수의 링크(2.4GHz, 5GHz, 6GHz 대역)를 통한 통신을 지원하는 다중 링크 장치(MLD)임. | S2: In a wireless local area network system, a receiving device may receive a Block Acknowledgment Request (BAR) frame including information related to a link for which an ACK is requested, and transmit a Block ACK (BA) frame on the basis of the BAR frame. The receiving device is a Multi-Link Device (MLD), which supports communication over multiple links. Each link of the multiple links can be configured based on 2.4 GHz band, 5 GHz band, and/or 6 GHz band defined in a conventional wireless local area network system. | T2: =COUNTA(_xlfn.TEXTSPLIT(Q2, "|")) -> 7 | U2: =_xlfn.LET( _xlpm.authors, _xlfn.TEXTSPLIT(Q2, "|"), _xlpm.countAuthors, COUNTA(_xlpm.authors), _xlpm.ratio, 1 / _xlpm.countAuthors, _xlpm.ratio ) -> 0.14285714 | V2: =300*표1[[#This Row],[열1]] -> 42.857143
A3: 2 | B3: US | C3: Multi-link channel access | D3: B2 | E3: 18216921 | F3: 2023.06.30 | G3: 20230345523 | H3: 2023.10.26 | I3: 12238761 | J3: 2025.02.25 | K3: 12238761 | P3: LG ELECTRONICS INC. | Q3: Insun Jang|Jeongki Kim|Jinsoo Choi|Suhwook Kim|Namyeong Kim|Sungjin Park|Taewon Song | R3: 무선 LAN 시스템에서 다중 링크 장치(MLD)가 비주요 링크의 백오프 카운터가 0에 도달해도 주요 링크의 백오프 카운터가 0에 도달하지 않은 경우 첫 번째 링크에서 PPDU 전송을 지연시키는 기술. 전송이 지연될 때 백오프 카운터는 0으로 유지됨. | S3: In a wireless local area network (WLAN) system, a transmitting multi-link device (MLD) may defer the transmission of a PPDU on a first link, even if a back-off counter of a non-primary link reaches zero, as long as a back-off counter of a primary link does not reach zero. When the transmission of the PPDU is deferred, the back-off counter may be kept at zero. | T3: =COUNTA(_xlfn.TEXTSPLIT(Q3, "|")) -> 7 | U3: =_xlfn.LET( _xlpm.authors, _xlfn.TEXTSPLIT(Q3, "|"), _xlpm.countAuthors, COUNTA(_xlpm.authors), _xlpm.ratio, 1 / _xlpm.countAuthors, _xlpm.ratio ) -> 0.14285714 | V3: =300*표1[[#This Row],[열1]] -> 42.857143
A4: 3 | B4: US | C4: Method for performing multi-link communication in wireless communication system | D4: B2 | E4: 18585787 | F4: 2024.02.23 | G4: 20240205998 | H4: 2024.06.20 | I4: 12219638 | J4: 2025.02.04 | K4: 12219638 | P4: LG ELECTRONICS INC. | Q4: Namyeong Kim|Jeongki Kim|Jinsoo Choi|Sungjin Park|Taewon Song|Insun Jang | R4: 다중 링크 장치(MLD)가 첫 번째 AP를 통해 요청 프레임을 전송하여 두 번째 링크에 대해 지정된 요소 세트에 포함된 모든 요소를 요청하고, 이에 기반하여 해당 요소들을 수신하는 기술. | S4: According to various embodiments, a multi-link device (MLD) operating in a plurality of links including a first link can transmit a request frame to a first AP of an AP MILD through a first STA (station), wherein the request frame includes an information field for requesting every element included in an element set designated for a second link. The MILD can, on the basis of the request frame, receive every element included in the element set designated for the second link. | T4: =COUNTA(_xlfn.TEXTSPLIT(Q4, "|")) -> 6 | U4: =_xlfn.LET( _xlpm.authors, _xlfn.TEXTSPLIT(Q4, "|"), _xlpm.countAuthors, COUNTA(_xlpm.authors), _xlpm.ratio, 1 / _xlpm.countAuthors, _xlpm.ratio ) -> 0.16666667 | V4: =300*표1[[#This Row],[열1]] -> 50
A5: 4 | B5: US | C5: Method for changing channel in multi-links | D5: B2 | E5: 17642624 | F5: 2020.09.03 | G5: 20220346176 | H5: 2022.10.27 | I5: 12219644 | J5: 2025.02.04 | K5: 12219644 | L5: PCT/KR2020/011838 | M5: 20200903 | N5: WO2021049817 | O5: 2021.03.18 | P5: LG ELECTRONICS INC. | Q5: Insun Jang|Jeongki Kim|Jinsoo Choi|Suhwook Kim|Sungjin Park|Taewon Song | R5: 무선 LAN 시스템에서 전송 장치가 다중 링크 채널 전환 기능 정보를 수신 장치에 전송하고, 첫 번째 링크를 통해 PPDU 및 채널 변경 신호를 전송한 후 두 번째 링크를 통해 PPDU를 전송하는 기술. | S5: Presented are a method by which a transmitting device performs channel switching between multi-links in a wireless local area network (LAN) system, and a device. Particularly, the method comprises the steps of: transmitting multi-link channel switching capability information to a receiving device, wherein the multi-link channel switching capability information includes information related to whether the transmitting device can perform channel changing between multi-link channels; transmitting a physical protocol data unit (PPDU) to the receiving device through a first link; transmitting a multi-link channel change signal to the receiving device through the first link; and transmitting the PPDU to the receiving device through a second link. | T5: =COUNTA(_xlfn.TEXTSPLIT(Q5, "|")) -> 6 | U5: =_xlfn.LET( _xlpm.authors, _xlfn.TEXTSPLIT(Q5, "|"), _xlpm.countAuthors, COUNTA(_xlpm.authors), _xlpm.ratio, 1 / _xlpm.countAuthors, _xlpm.ratio ) -> 0.16666667 | V5: =300*표1[[#This Row],[열1]] -> 50
A6: 5 | B6: US | C6: Transmission of capability information about link | D6: B2 | E6: 17798820 | F6: 2020.12.22 | G6: 20230164634 | H6: 2023.05.25 | I6: 12200544 | J6: 2025.01.14 | K6: 12200544 | L6: PCT/KR2020/018878 | M6: 20201222 | N6: WO2021162234 | O6: 2021.08.19 | P6: LG ELECTRONICS INC. | Q6: Insun Jang|Jeongki Kim|Jinsoo Choi|Namyeong Kim|Suhwook Kim|Sungjin Park|Taewon Song | R6: 무선 LAN 시스템에서 비AP 스테이션 MLD가 첫 번째 링크를 통해 최대 공간 스트림(NSS) 정보가 포함된 협상 프레임을 AP MLD에 전송하고, 협상 응답 프레임을 수신하는 기술. | S6: The present disclosure relates to a method performed by a non-access point (AP) station (STA) multi-link device (MLD) of a wireless LAN system, the method comprising the steps of: transmitting, through a first link, a negotiation frame including first maximum number of spatial stream (NSS) information to an AP MLD; and receiving a negotiation response frame from the AP MLD through the first link. | T6: =COUNTA(_xlfn.TEXTSPLIT(Q6, "|")) -> 7 | U6: =_xlfn.LET( _xlpm.authors, _xlfn.TEXTSPLIT(Q6, "|"), _xlpm.countAuthors, COUNTA(_xlpm.authors), _xlpm.ratio, 1 / _xlpm.countAuthors, _xlpm.ratio ) -> 0.14285714 | V6: =300*표1[[#This Row],[열1]] -> 42.857143
A7: 6 | B7: US | C7: Technique for performing multi-link communication in wireless communication system | D7: B2 | E7: 17910692 | F7: 2021.03.16 | G7: 20230164661 | H7: 2023.05.25 | I7: 12192875 | J7: 2025.01.07 | K7: 12192875 | L7: PCT/KR2021/003221 | M7: 20210316 | N7: WO2021187858 | O7: 2021.09.23 | P7: LG ELECTRONICS INC. | Q7: Namyeong Kim|Jeongki Kim|Jinsoo Choi|Sungjin Park|Taewon Song|Insun Jang | R7: 다중 링크 장치(MLD)가 첫 번째 링크를 통해 PPDU를 수신하는데, 이 PPDU에는 두 번째 링크와 관련된 정보 필드가 포함됨. 이 정보 필드는 두 번째 링크의 식별자와 관련된 정보와 두 번째 링크에 관련된 모든 요소 정보가 PPDU에 포함되어 있는지 여부에 대한 정보를 포함함. | S7: According to various embodiments, a multi-link device (MLD) operating in a plurality of links can receive a PPDU through a first link from among the plurality of links. The PPU can include a first information field related to a second link that is differentiated from the first link. The first information field related to a second link can include a second information field related to a link identifier of a second link and a third information field related to whether all pieces of element information related to a second link is included in the PPDU. | T7: =COUNTA(_xlfn.TEXTSPLIT(Q7, "|")) -> 6 | U7: =_xlfn.LET( _xlpm.authors, _xlfn.TEXTSPLIT(Q7, "|"), _xlpm.countAuthors, COUNTA(_xlpm.authors), _xlpm.ratio, 1 / _xlpm.countAuthors, _xlpm.ratio ) -> 0.16666667 | V7: =300*표1[[#This Row],[열1]] -> 50
A8: 7 | B8: US | C8: NACK frame for HARQ operation | D8: B2 | E8: 17606714 | F8: 2020.04.16 | G8: 20220231797 | H8: 2022.07.21 | I8: 12184426 | J8: 2024.12.31 | K8: 12184426 | L8: PCT/KR2020/005100 | M8: 20200416 | N8: WO2020222446 | O8: 2020.11.05 | P8: LG ELECTRONICS INC. | Q8: Taewon Song|Kiseon Ryu|Jeongki Kim|Jinsoo Choi|Suhwook Kim|Insun Jang | R8: 무선 LAN 시스템에서 전송 장치가 첫 번째 중복 버전의 전송 데이터가 포함된 PPDU를 수신 장치에 전송하고, ACK 또는 NACK 프레임이 임계 시간 내에 수신되는지 여부에 따라 재전송할 두 번째 중복 버전을 결정하는 기술. | S8: In a wireless local area network (LAN) system, a transmission station (STA) may transmit, to a receiving STA, a PHY protocol data unit (PPDU) including a first redundancy version of transmission data. On the basis of whether an acknowledgement (ACK) or negative ACK (NACK) frame is received within a threshold time, the transmission STA may determine a second redundancy version of the transmission data to be retransmitted. | T8: =COUNTA(_xlfn.TEXTSPLIT(Q8, "|")) -> 6 | U8: =_xlfn.LET( _xlpm.authors, _xlfn.TEXTSPLIT(Q8, "|"), _xlpm.countAuthors, COUNTA(_xlpm.authors), _xlpm.ratio, 1 / _xlpm.countAuthors, _xlpm.ratio ) -> 0.16666667 | V8: =300*표1[[#This Row],[열1]] -> 50
A9: 8 | B9: US | C9: Mapping of TID and link in multi-link | D9: B2 | E9: 17597170 | F9: 2020.06.22 | G9: 20220312522 | H9: 2022.09.29 | I9: 12177914 | J9: 2024.12.24 | K9: 12177914 | L9: PCT/KR2020/008060 | M9: 20200622 | N9: WO2021002617 | O9: 2021.01.07 | P9: LG ELECTRONICS INC. | Q9: Insun Jang|Jeongki Kim|Jinsoo Choi|Suhwook Kim|Sungjin Park|Taewon Song | R9: 무선 LAN 시스템에서 스테이션(STA)이 첫 번째 TID가 첫 번째 링크에 매핑되고 두 번째 TID가 두 번째 링크에 매핑됨을 나타내는 정보가 포함된 PPDU를 전송하여, 각 TID에 해당하는 트래픽을 지정된 링크를 통해서만 전송하는 기술. | S9: In a wireless local area network (LAN) system, a station (STA) may transmit a first physical protocol data unit (PPDU) including information indicating that a first traffic identifier (TID) is mapped to a first link and a second TID is mapped to a second link. The STA may transmit traffic pertaining to the first TID through only the first link, and traffic pertaining to the second TID through only the second link. | T9: =COUNTA(_xlfn.TEXTSPLIT(Q9, "|")) -> 6 | U9: =_xlfn.LET( _xlpm.authors, _xlfn.TEXTSPLIT(Q9, "|"), _xlpm.countAuthors, COUNTA(_xlpm.authors), _xlpm.ratio, 1 / _xlpm.countAuthors, _xlpm.ratio ) -> 0.16666667 | V9: =300*표1[[#This Row],[열1]] -> 50
A10: 9 | B10: US | C10: MPDU padding for HARQ operation | D10: B2 | E10: 17600993 | F10: 2020.04.06 | G10: 20220167319 | H10: 2022.05.26 | I10: 12150098 | J10: 2024.11.19 | K10: 12150098 | L10: PCT/KR2020/004629 | M10: 20200406 | N10: WO2020209558 | O10: 2020.10.15 | P10: LG ELECTRONICS INC. | Q10: Taewon Song|Kiseon Ryu|Jeongki Kim|Jinsoo Choi|Suhwook Kim|Jinmin Kim|Insun Jang | R10: 무선 LAN 시스템에서 스테이션(STA)이 서브프레임 길이 정보와 함께 하나 이상의 서브프레임을 포함하는 PPDU를 생성하는 기술. 서브프레임은 MPDU와 패딩 비트를 포함하며, 패딩 비트 길이는 서브프레임 길이가 코드워드 길이의 정수배가 되도록 결정됨. | S10: In a wireless local area network system, a station (STA) generates a physical (PHY) protocol data unit (PPDU) including at least one subframe and information related to a subframe length, wherein the subframe may include a medium access control (MAC) protocol data unit (MPDU) and a padding bit. The length of the padding bit may be determined such that the length of the subframes is an integer multiple of a codeword length. The information related to the subframe length may be information on the number of codewords related to the subframe length. A step in which the STA transmits the PPDU may be comprised. | T10: =COUNTA(_xlfn.TEXTSPLIT(Q10, "|")) -> 7 | U10: =_xlfn.LET( _xlpm.authors, _xlfn.TEXTSPLIT(Q10, "|"), _xlpm.countAuthors, COUNTA(_xlpm.authors), _xlpm.ratio, 1 / _xlpm.countAuthors, _xlpm.ratio ) -> 0.14285714 | V10: =300*표1[[#This Row],[열1]] -> 42.857143
A11: 10 | B11: US | C11: Method for performing multi-link communication in wireless communication system | D11: B2 | E11: 17908801 | F11: 2021.03.05 | G11: 20230345349 | H11: 2023.10.26 | I11: 12133162 | J11: 2024.10.29 | K11: 12133162 | L11: PCT/KR2021/002737 | M11: 20210305 | N11: WO2021177774 | O11: 2021.09.10 | P11: LG ELECTRONICS INC. | Q11: Namyeong Kim|Jeongki Kim|Jinsoo Choi|Sungjin Park|Taewon Song|Insun Jang | R11: 다중 링크 장치(MLD)가 첫 번째 스테이션(STA)을 통해 AP 다중 링크 장치의 첫 번째 AP에 두 번째 링크와 관련된 요소를 요청하는 정보 필드가 포함된 요청 프레임을 전송하고, 이 요청에 기반하여 두 번째 링크와 관련된 요소를 수신하는 기술. | S11: According to various embodiments, a multi-link device (MLD) operating in multiple links including a first link may transmit, through a first station (STA) and to a first AP of an AP multi-link device, a request frame including an information field for requesting at least one element related to a second link. The multi-link device may receive at least one element related to the second link on the basis of the request frame. | T11: =COUNTA(_xlfn.TEXTSPLIT(Q11, "|")) -> 6 | U11: =_xlfn.LET( _xlpm.authors, _xlfn.TEXTSPLIT(Q11, "|"), _xlpm.countAuthors, COUNTA(_xlpm.authors), _xlpm.ratio, 1 / _xlpm.countAuthors, _xlpm.ratio ) -> 0.16666667 | V11: =300*표1[[#This Row],[열1]] -> 50
A12: 11 | B12: US | C12: Mapping of TID and link in multi-link | D12: B2 | E12: 18210913 | F12: 2023.06.16 | G12: 20230337306 | H12: 2023.10.19 | I12: 12120763 | J12: 2024.10.15 | K12: 12120763 | P12: LG ELECTRONICS INC. | Q12: Insun Jang|Jeongki Kim|Jinsoo Choi|Suhwook Kim|Sungjin Park|Taewon Song | R12: 무선 LAN 시스템에서 스테이션(STA)이 첫 번째 TID가 첫 번째 링크에 매핑되고 두 번째 TID가 두 번째 링크에 매핑됨을 나타내는 정보가 포함된 PPDU를 전송하여, 각 TID에 해당하는 트래픽을 지정된 링크를 통해서만 전송하는 기술. | S12: In a wireless local area network (LAN) system, a station (STA) may transmit a first physical protocol data unit (PPDU) including information indicating that a first traffic identifier (TID) is mapped to a first link and a second TID is mapped to a second link. The STA may transmit traffic pertaining to the first TID through only the first link, and traffic pertaining to the second TID through only the second link. | T12: =COUNTA(_xlfn.TEXTSPLIT(Q12, "|")) -> 6 | U12: =_xlfn.LET( _xlpm.authors, _xlfn.TEXTSPLIT(Q12, "|"), _xlpm.countAuthors, COUNTA(_xlpm.authors), _xlpm.ratio, 1 / _xlpm.countAuthors, _xlpm.ratio ) -> 0.16666667 | V12: =300*표1[[#This Row],[열1]] -> 50
A13: 12 | B13: US | C13: Method for performing multi-link communication in wireless communication system | D13: B2 | E13: 18218898 | F13: 2023.07.06 | G13: 20230354452 | H13: 2023.11.02 | I13: 12089140 | J13: 2024.09.10 | K13: 12089140 | P13: LG ELECTRONICS INC. | Q13: Namyeong Kim|Jeongki Kim|Jinsoo Choi|Sungjin Park|Taewon Song|Insun Jang | R13: 다중 링크 장치(MLD)가 첫 번째 스테이션(STA)을 통해 AP 다중 링크 장치의 첫 번째 AP에 두 번째 링크와 관련된 요소를 요청하는 정보 필드가 포함된 요청 프레임을 전송하고, 이 요청에 기반하여 두 번째 링크와 관련된 요소를 수신하는 기술. | S13: According to various embodiments, a multi-link device (MLD) operating in multiple links including a first link may transmit, through a first station (STA) and to a first AP of an AP multi-link device, a request frame including an information field for requesting at least one element related to a second link. The multi-link device may receive at least one element related to the second link on the basis of the request frame. | T13: =COUNTA(_xlfn.TEXTSPLIT(Q13, "|")) -> 6 | U13: =_xlfn.LET( _xlpm.authors, _xlfn.TEXTSPLIT(Q13, "|"), _xlpm.countAuthors, COUNTA(_xlpm.authors), _xlpm.ratio, 1 / _xlpm.countAuthors, _xlpm.ratio ) -> 0.16666667 | V13: =300*표1[[#This Row],[열1]] -> 50
A14: 13 | B14: US | C14: Multi-link RTS and CTS transmissions | D14: B2 | E14: 18597164 | F14: 2024.03.06 | G14: 20240215070 | H14: 2024.06.27 | I14: 12089255 | J14: 2024.09.10 | K14: 12089255 | P14: LG ELECTRONICS INC. | Q14: Insun Jang|Jeongki Kim|Jinsoo Choi|Namyeong Kim|Suhwook Kim|Sungjin Park|Taewon Song | R14: 무선 LAN 시스템에서 수신 다중 링크 장치(MLD)가 두 번째 링크를 통해 RTS 프레임을 수신해도, 첫 번째 링크를 통해 작동하는 STA가 TXOP 응답자인 경우 CTS 프레임을 전송하지 않는 기술. 다중 링크 장치는 최소한 하나의 NSTR(비동시 송수신) 링크 쌍을 포함함. | S14: In a wireless local area network system, a reception multi-link device (MLD) may not transmit a CTS frame, even if the reception multi-link device receives an RTS frame via a second link, in the case that an STA operating via a first link is a TXOP responder. In detail, the reception MLD may include at least one non-simultaneous transmit and receive (NSTR) link pair. A first STA affiliated with the MLD may determine to respond with the CTS frame to the RTS frame. The first STA does not respond with the CTS frame based on another STA being a transmission opportunity (TXOP) responder on another link. | T14: =COUNTA(_xlfn.TEXTSPLIT(Q14, "|")) -> 7 | U14: =_xlfn.LET( _xlpm.authors, _xlfn.TEXTSPLIT(Q14, "|"), _xlpm.countAuthors, COUNTA(_xlpm.authors), _xlpm.ratio, 1 / _xlpm.countAuthors, _xlpm.ratio ) -> 0.14285714 | V14: =300*표1[[#This Row],[열1]] -> 42.857143
